<mujoco model="dual_arm">
  <compiler angle="radian" meshdir="assets"/>
  <option integrator="implicitfast" cone="elliptic" impratio="10"/>

  <default>
    <default class="visual">
      <geom type="mesh" contype="0" conaffinity="0" density="0" group="2"/>
    </default>
    <default class="collision">
      <geom group="3"/>
    </default>
  </default>

  <asset>
    <material name="silver_default" rgba="0.75 0.75 0.78 1.0"/>
    <material name="silver_box" rgba="0.8 0.8 0.85 1.0"/>
    <material name="camera" rgba="0.1 0.1 0.1 1.0"/>
    <material name="gray" rgba="0.6 0.6 0.6 1.0"/>
    <material name="green" rgba="0.0 1.0 0.0 1.0"/>
    <material name="blue" rgba="0.0 0.0 1.0 1.0"/>

    <mesh name="base_link" file="base_link.stl" scale="0.001 0.001 0.001"/>
    <mesh name="dof1_1" file="DOF1_1.stl" scale="0.001 0.001 0.001"/>
    <mesh name="dof1_link_1" file="DOF1_LINK_1.stl" scale="0.001 0.001 0.001"/>
    <mesh name="dof2_1" file="DOF2_1.stl" scale="0.001 0.001 0.001"/>
    <mesh name="dof3_motor_1" file="DOF3_MOTOR_1.stl" scale="0.001 0.001 0.001"/>
    <mesh name="dof3_link_1" file="DOF3_LINK_1.stl" scale="0.001 0.001 0.001"/>
    <mesh name="dof4_1" file="DOF4_1.stl" scale="0.001 0.001 0.001"/>
    <mesh name="dof5_motor_1" file="DOF5_MOTOR_1.stl" scale="0.001 0.001 0.001"/>
    <mesh name="dof5_link_1" file="DOF5_LINK_1.stl" scale="0.001 0.001 0.001"/>
    <mesh name="dof6_link_1" file="DOF6_LINK_1.stl" scale="0.001 0.001 0.001"/>
    <mesh name="dof7_motor_1" file="DOF7_MOTOR_1.stl" scale="0.001 0.001 0.001"/>
    <mesh name="top_1" file="TOP_1.stl" scale="0.001 0.001 0.001"/>

    <mesh name="rh_hand_dummy_link" file="right_hand/Hand_Dummy_Link.stl" scale="0.001 0.001 0.001"/>
    <mesh name="rh_mid_1" file="right_hand/Mid_1.stl" scale="0.001 0.001 0.001"/>
    <mesh name="rh_top_1" file="right_hand/Top_1.stl" scale="0.001 0.001 0.001"/>
    <mesh name="rh_mid_2" file="right_hand/Mid_2.stl" scale="0.001 0.001 0.001"/>
    <mesh name="rh_top_2" file="right_hand/Top_2.stl" scale="0.001 0.001 0.001"/>
    <mesh name="rh_mid_3" file="right_hand/Mid_3.stl" scale="0.001 0.001 0.001"/>
    <mesh name="rh_top_3" file="right_hand/Top_3.stl" scale="0.001 0.001 0.001"/>

    <mesh name="lh_hand_dummy_link" file="left_hand/Hand_Dummy_Link.stl" scale="0.001 0.001 0.001"/>
    <mesh name="lh_mid_1" file="left_hand/Mid_1.stl" scale="0.001 0.001 0.001"/>
    <mesh name="lh_top_1" file="left_hand/Top_1.stl" scale="0.001 0.001 0.001"/>
    <mesh name="lh_mid_2" file="left_hand/Mid_2.stl" scale="0.001 0.001 0.001"/>
    <mesh name="lh_top_2" file="left_hand/Top_2.stl" scale="0.001 0.001 0.001"/>
    <mesh name="lh_mid_3" file="left_hand/Mid_3.stl" scale="0.001 0.001 0.001"/>
    <mesh name="lh_top_3" file="left_hand/Top_3.stl" scale="0.001 0.001 0.001"/>

  </asset>

  <worldbody>
    <light pos="0 0 1.5" dir="0 0 -1" directional="true"/>
    <body name="base_link">
      <inertial pos="0 0 0.4" mass="5" fullinertia="0.2 0.26 0.1 0 0 0"/>
      <geom class="visual" type="box" size="0.13 0.08 0.4" pos="0 0 0.4" material="silver_box"/>
      <geom class="collision" type="box" size="0.13 0.08 0.4" pos="0 0 0.4"/>
      <body name="camera_link" pos="0.13 0 0.9" quat="1 0 0 0">
          <inertial pos="0 0 0" mass="0.2" fullinertia="0.00015 5e-05 0.00012 0 0 0"/>
          <geom class="visual" type="box" size="0.025 0.09 0.015" quat="0.921060994 0 -0.3894183423 0" material="camera"/>
          <geom class="collision" type="box" size="0.025 0.09 0.015" quat="0.921060994 0 -0.3894183423 0"/>
      </body>
      <body name="right_base_link" pos="0 -0.08 0.7" quat="0.5000031634 0.5 -0.5 0.4999968366">
          <inertial pos="3.041253315e-05 3.52336381e-06 0.03438637774" mass="0.2889719789" fullinertia="0.000561 0.000389 0.000553 -0 -0 0"/>
          <geom class="visual" mesh="base_link" material="silver_default"/>
          <geom class="collision" mesh="base_link"/>
          <body name="right_DOF1_1" pos="0 4e-06 0.069966" quat="1 0 0 0">
              <inertial pos="-0.0001596090655 -1.242784501e-05 -0.03023580689" mass="0.6510136315" fullinertia="0.000498 0.000484 0.000407 0 -3e-06 -0"/>
              <geom class="visual" mesh="dof1_1" pos="-0 -4e-06 -0.069966" material="silver_default"/>
              <geom class="collision" mesh="dof1_1" pos="-0 -4e-06 -0.069966"/>
          </body>
          <body name="right_DOF1_LINK_1" pos="0 4e-06 0.074366" quat="1 0 0 0">
            <joint name="right_Rev2" type="hinge" axis="0 0 1" range="-3.141592654 3.141592654"/>
              <inertial pos="5.208552757e-06 0.0049778954 0.07010343108" mass="0.9352929404" fullinertia="0.001224 0.001136 0.00072 -0 -0 -4.3e-05"/>
              <geom class="visual" mesh="dof1_link_1" pos="-0 -4e-06 -0.074366" material="silver_default"/>
              <geom class="collision" mesh="dof1_link_1" pos="-0 -4e-06 -0.074366"/>
              <body name="right_DOF2_1" pos="-0 -0.025 0.0812" quat="1 0 0 0">
                <joint name="right_Rev3" type="hinge" axis="0 1 -0" range="-3.141592654 3.141592654"/>
                  <inertial pos="-3.192121649e-08 -0.01167950146 0.04696474149" mass="0.5984706719" fullinertia="0.001836 0.001772 0.000381 0 -0 -0.000265"/>
                  <geom class="visual" mesh="dof2_1" pos="0 0.024996 -0.155566" material="silver_default"/>
                  <geom class="collision" mesh="dof2_1" pos="0 0.024996 -0.155566"/>
                  <body name="right_DOF3_MOTOR_1" pos="0 0.0255 0.122897" quat="1 0 0 0">
                      <inertial pos="7.926931011e-05 3.749110346e-05 -0.03134589115" mass="0.5847003223" fullinertia="0.000404 0.00039 0.000324 0 2e-06 1e-06"/>
                      <geom class="visual" mesh="dof3_motor_1" pos="0 -0.000504 -0.278463" material="silver_default"/>
                      <geom class="collision" mesh="dof3_motor_1" pos="0 -0.000504 -0.278463"/>
                  </body>
                  <body name="right_DOF3_LINK_1" pos="0 0.0255 0.127897" quat="1 0 0 0">
                    <joint name="right_Rev6" type="hinge" axis="0 -0 -1" range="-3.141592654 3.141592654"/>
                      <inertial pos="-5.211227425e-06 -0.00497808782 0.07040264167" mass="0.9352929404" fullinertia="0.001224 0.001136 0.00072 -0 0 4.3e-05"/>
                      <geom class="visual" mesh="dof3_link_1" pos="0 -0.000504 -0.283463" material="silver_default"/>
                      <geom class="collision" mesh="dof3_link_1" pos="0 -0.000504 -0.283463"/>
                      <body name="right_DOF4_1" pos="0 0.025 0.0815" quat="1 0 0 0">
                        <joint name="right_Rev7" type="hinge" axis="0 -1 -0" range="-3.141592654 3.141592654"/>
                          <inertial pos="2.926145802e-08 0.01167930904 0.04696395209" mass="0.5984706719" fullinertia="0.001836 0.001772 0.000381 0 0 0.000265"/>
                          <geom class="visual" mesh="dof4_1" pos="0 -0.025504 -0.364963" material="silver_default"/>
                          <geom class="collision" mesh="dof4_1" pos="0 -0.025504 -0.364963"/>
                          <body name="right_DOF5_MOTOR_1" pos="0 -0.0255 0.122896" quat="1 0 0 0">
                              <inertial pos="-7.927197129e-05 -3.768352768e-05 -0.03134568056" mass="0.5847003223" fullinertia="0.000404 0.00039 0.000324 0 -2e-06 -1e-06"/>
                              <geom class="visual" mesh="dof5_motor_1" pos="-0 -4e-06 -0.487859" material="silver_default"/>
                              <geom class="collision" mesh="dof5_motor_1" pos="-0 -4e-06 -0.487859"/>
                          </body>
                          <body name="right_DOF5_link_1" pos="0 -0.0255 0.127896" quat="1 0 0 0">
                            <joint name="right_Rev9" type="hinge" axis="-0 0 -1" range="-3.141592654 3.141592654"/>
                              <inertial pos="5.208648523e-06 0.004977895392 0.07010285226" mass="0.9352929404" fullinertia="0.001224 0.001136 0.00072 -0 -0 -4.3e-05"/>
                              <geom class="visual" mesh="dof5_link_1" pos="-0 -4e-06 -0.492859" material="silver_default"/>
                              <geom class="collision" mesh="dof5_link_1" pos="-0 -4e-06 -0.492859"/>
                              <body name="right_DOF6_LINK_1" pos="0 -0.025 0.0812" quat="1 0 0 0">
                                <joint name="right_Rev10" type="hinge" axis="0 1 0" range="-3.141592654 3.141592654"/>
                                  <inertial pos="-3.175600208e-08 -0.01167950147 0.04696416268" mass="0.5984706719" fullinertia="0.001836 0.001772 0.000381 0 -0 -0.000265"/>
                                  <geom class="visual" mesh="dof6_link_1" pos="-0 0.024996 -0.574059" material="silver_default"/>
                                  <geom class="collision" mesh="dof6_link_1" pos="-0 0.024996 -0.574059"/>
                                  <body name="right_DOF7_MOTOR_1" pos="-0 0.0255 0.122896" quat="1 0 0 0">
                                      <inertial pos="7.926952865e-05 3.749109242e-05 -0.03134546996" mass="0.5847003223" fullinertia="0.000404 0.00039 0.000324 0 2e-06 1e-06"/>
                                      <geom class="visual" mesh="dof7_motor_1" pos="0 -0.000504 -0.696955" material="silver_default"/>
                                      <geom class="collision" mesh="dof7_motor_1" pos="0 -0.000504 -0.696955"/>
                                  </body>
                                  <body name="right_TOP_1" pos="-0 0.0255 0.127896" quat="1 0 0 0">
                                      <inertial pos="-4.963925281e-07 -0.0001958278333 0.01611980647" mass="0.1530238863" fullinertia="4.6e-05 5e-05 5.5e-05 0 0 0"/>
                                      <geom class="visual" mesh="top_1" pos="0 -0.000504 -0.701955" material="silver_default"/>
                                      <geom class="collision" mesh="top_1" pos="0 -0.000504 -0.701955"/>
                                      <body name="right_wrist_link" pos="0 0 0.034" quat="1 0 0 0">
                                        <joint name="right_wrist" type="hinge" axis="-0 0 1" range="-3.141592654 3.141592654"/>
                                          <inertial pos="0 0 0" mass="1e-06" fullinertia="1e-09 1e-09 1e-09 0 0 0"/>
                                          <body name="right_Hand_Dummy_Link" pos="-0.0056 0.0126 0.06" quat="0.6618783286 0.2493588965 -0.6614811861 -0.2493588965">
                                              <!-- site 추가-->
                                              <site name="gripper_right" pos="0 0 0" size="0.002"/>
                                              <inertial pos="0.005220094871 -0.01266226649 -0.002339754105" mass="0.4104004357" fullinertia="0.0002736560868 0.0003665647338 0.0002693697631 -1.625998744e-05 -2.20916206e-05 -3.736178695e-06"/>
                                              <geom class="visual" mesh="rh_hand_dummy_link" material="blue"/>
                                              <geom class="collision" mesh="rh_hand_dummy_link"/>
                                              <body name="right_Mid_1" pos="0.0195 0 0.044925" quat="5.467576059e-17 0.892922933 -0.4502095465 -2.756738401e-17">
                                                <joint name="right_Dummy_Mid_1" type="hinge" axis="0 0 -1" range="-3.141592654 3.141592654"/>
                                                  <inertial pos="0.005334347821 -0.02491453815 0.02688776818" mass="0.01135237004" fullinertia="5.979679537e-06 3.332989236e-06 3.378107333e-06 4.309385545e-07 -1.501682585e-07 1.017742283e-06"/>
                                                  <geom class="visual" mesh="rh_mid_1" pos="-0.01688749537 0.00975 0.045" quat="5.914589857e-17 0.9659258263 -0.2588190451 -1.584809576e-17" material="gray"/>
                                                  <geom class="collision" mesh="rh_mid_1" pos="-0.01688749537 0.00975 0.045" quat="5.914589857e-17 0.9659258263 -0.2588190451 -1.584809576e-17"/>
                                                  <body name="right_Top_1" pos="0.005 -0.05 0.0265" quat="6.123233996e-17 1 0 0">
                                                    <joint name="right_Mid_Top_1" type="hinge" axis="0 0 1" range="-3.141592654 3.141592654"/>
                                                      <inertial pos="0.0002305755848 0.02925119685 -0.008499997206" mass="0.01814208712" fullinertia="3.336963225e-06 1.006672348e-06 3.173651597e-06 -6.343535417e-09 -2.206247151e-14 -7.149330447e-13"/>
                                                      <geom class="visual" mesh="rh_top_1" pos="-0.04883012702 -0.04080127019 -0.0185" material="green"/>
                                                      <geom class="collision" mesh="rh_top_1" pos="-0.04883012702 -0.04080127019 -0.0185"/>
                                                  </body>
                                              </body>
                                              <body name="right_Mid_2" pos="0.0195 0 -0.044925" quat="0.892922933 0 0 -0.4502095465">
                                                <joint name="right_Dummy_Mid_2" type="hinge" axis="0 0 1" range="-3.141592654 3.141592654"/>
                                                  <inertial pos="0.006022289852 0.02650814878 0.02425888271" mass="0.01158754004" fullinertia="6.612672074e-06 3.675596271e-06 3.731369524e-06 -5.395393065e-07 -1.132389457e-07 -6.146722883e-07"/>
                                                  <geom class="visual" mesh="rh_mid_2" pos="-0.01883555361 -0.005046971379 0.045" quat="0.9914448614 0 0 0.1305261922" material="gray"/>
                                                  <geom class="collision" mesh="rh_mid_2" pos="-0.01883555361 -0.005046971379 0.045" quat="0.9914448614 0 0 0.1305261922"/>
                                                  <body name="right_Top_2" pos="0.005 0.05 0.0135" quat="1 0 0 1.387778781e-17">
                                                    <joint name="right_Mid_Top_2" type="hinge" axis="0 0 1" range="-3.141592654 3.141592654"/>
                                                      <inertial pos="-0.0001840590108 0.02972236312 0.01499999855" mass="0.03008198439" fullinertia="7.380892306e-06 3.54850512e-06 5.293784031e-06 -1.203299422e-07 4.583632295e-13 7.215562173e-13"/>
                                                      <geom class="visual" mesh="rh_top_2" pos="-0.05996283905 -0.001661507511 0.0315" quat="0.906307787 0 0 -0.4226182617" material="green"/>
                                                      <geom class="collision" mesh="rh_top_2" pos="-0.05996283905 -0.001661507511 0.0315" quat="0.906307787 0 0 -0.4226182617"/>
                                                  </body>
                                              </body>
                                              <body name="right_Mid_3" pos="-0.0195 0 0.016425" quat="5.467576059e-17 0.892922933 0.4502095465 2.756738401e-17">
                                                <joint name="right_Dummy_Mid_3" type="hinge" axis="0 0 1" range="-3.141592654 3.141592654"/>
                                                  <inertial pos="-0.005971229547 -0.02625242373 0.02199999972" mass="0.01187855709" fullinertia="6.646984159e-06 3.666402675e-06 3.793976934e-06 -5.506825936e-07 8.238334094e-14 1.039543514e-13"/>
                                                  <geom class="visual" mesh="rh_mid_3" pos="0.01883555361 0.005046971379 0.0165" quat="6.07084888e-17 0.9914448614 0.1305261922 7.992424175e-18" material="gray"/>
                                                  <geom class="collision" mesh="rh_mid_3" pos="0.01883555361 0.005046971379 0.0165" quat="6.07084888e-17 0.9914448614 0.1305261922 7.992424175e-18"/>
                                                  <body name="right_Top_3" pos="-0.005 -0.05 0.007" quat="1 0 0 0">
                                                    <joint name="right_Mid_Top_3" type="hinge" axis="0 0 1" range="-3.141592654 3.141592654"/>
                                                      <inertial pos="0.0001840590108 -0.02972236312 0.01499999841" mass="0.03008198439" fullinertia="7.38089226e-06 3.548505074e-06 5.293784031e-06 -1.203299422e-07 -2.09506459e-13 -5.909060015e-13"/>
                                                      <geom class="visual" mesh="rh_top_3" pos="0.05996283905 0.001661507511 0.0095" quat="2.470384401e-15 0.906307787 -0.4226182617 -1.151959165e-15" material="green"/>
                                                      <geom class="collision" mesh="rh_top_3" pos="0.05996283905 0.001661507511 0.0095" quat="2.470384401e-15 0.906307787 -0.4226182617 -1.151959165e-15"/>
                                                  </body>
                                              </body>
                                          </body>
                                      </body>
                                  </body>
                              </body>
                          </body>
                      </body>
                  </body>
              </body>
          </body>
      </body>
      <body name="left_base_link" pos="0 0.08 0.7" quat="0.5000031634 -0.4999968366 -0.5 -0.5">
          <inertial pos="3.041253315e-05 3.52336381e-06 0.03438637774" mass="0.2889719789" fullinertia="0.000561 0.000389 0.000553 -0 -0 0"/>
          <geom class="visual" mesh="base_link" material="silver_default"/>
          <geom class="collision" mesh="base_link"/>
          <body name="left_DOF1_1" pos="0 4e-06 0.069966" quat="1 0 0 0">
              <inertial pos="-0.0001596090655 -1.242784501e-05 -0.03023580689" mass="0.6510136315" fullinertia="0.000498 0.000484 0.000407 0 -3e-06 -0"/>
              <geom class="visual" mesh="dof1_1" pos="-0 -4e-06 -0.069966" material="silver_default"/>
              <geom class="collision" mesh="dof1_1" pos="-0 -4e-06 -0.069966"/>
          </body>
          <body name="left_DOF1_LINK_1" pos="0 4e-06 0.074366" quat="1 0 0 0">
            <joint name="left_Rev2" type="hinge" axis="0 0 1" range="-3.141592654 3.141592654"/>
              <inertial pos="5.208552757e-06 0.0049778954 0.07010343108" mass="0.9352929404" fullinertia="0.001224 0.001136 0.00072 -0 -0 -4.3e-05"/>
              <geom class="visual" mesh="dof1_link_1" pos="-0 -4e-06 -0.074366" material="silver_default"/>
              <geom class="collision" mesh="dof1_link_1" pos="-0 -4e-06 -0.074366"/>
              <body name="left_DOF2_1" pos="-0 -0.025 0.0812" quat="1 0 0 0">
                <joint name="left_Rev3" type="hinge" axis="0 1 -0" range="-3.141592654 3.141592654"/>
                  <inertial pos="-3.192121649e-08 -0.01167950146 0.04696474149" mass="0.5984706719" fullinertia="0.001836 0.001772 0.000381 0 -0 -0.000265"/>
                  <geom class="visual" mesh="dof2_1" pos="0 0.024996 -0.155566" material="silver_default"/>
                  <geom class="collision" mesh="dof2_1" pos="0 0.024996 -0.155566"/>
                  <body name="left_DOF3_MOTOR_1" pos="0 0.0255 0.122897" quat="1 0 0 0">
                      <inertial pos="7.926931011e-05 3.749110346e-05 -0.03134589115" mass="0.5847003223" fullinertia="0.000404 0.00039 0.000324 0 2e-06 1e-06"/>
                      <geom class="visual" mesh="dof3_motor_1" pos="0 -0.000504 -0.278463" material="silver_default"/>
                      <geom class="collision" mesh="dof3_motor_1" pos="0 -0.000504 -0.278463"/>
                  </body>
                  <body name="left_DOF3_LINK_1" pos="0 0.0255 0.127897" quat="1 0 0 0">
                    <joint name="left_Rev6" type="hinge" axis="0 -0 -1" range="-3.141592654 3.141592654"/>
                      <inertial pos="-5.211227425e-06 -0.00497808782 0.07040264167" mass="0.9352929404" fullinertia="0.001224 0.001136 0.00072 -0 0 4.3e-05"/>
                      <geom class="visual" mesh="dof3_link_1" pos="0 -0.000504 -0.283463" material="silver_default"/>
                      <geom class="collision" mesh="dof3_link_1" pos="0 -0.000504 -0.283463"/>
                      <body name="left_DOF4_1" pos="0 0.025 0.0815" quat="1 0 0 0">
                        <joint name="left_Rev7" type="hinge" axis="0 -1 -0" range="-3.141592654 3.141592654"/>
                          <inertial pos="2.926145802e-08 0.01167930904 0.04696395209" mass="0.5984706719" fullinertia="0.001836 0.001772 0.000381 0 0 0.000265"/>
                          <geom class="visual" mesh="dof4_1" pos="0 -0.025504 -0.364963" material="silver_default"/>
                          <geom class="collision" mesh="dof4_1" pos="0 -0.025504 -0.364963"/>
                          <body name="left_DOF5_MOTOR_1" pos="0 -0.0255 0.122896" quat="1 0 0 0">
                              <inertial pos="-7.927197129e-05 -3.768352768e-05 -0.03134568056" mass="0.5847003223" fullinertia="0.000404 0.00039 0.000324 0 -2e-06 -1e-06"/>
                              <geom class="visual" mesh="dof5_motor_1" pos="-0 -4e-06 -0.487859" material="silver_default"/>
                              <geom class="collision" mesh="dof5_motor_1" pos="-0 -4e-06 -0.487859"/>
                          </body>
                          <body name="left_DOF5_link_1" pos="0 -0.0255 0.127896" quat="1 0 0 0">
                            <joint name="left_Rev9" type="hinge" axis="-0 0 -1" range="-3.141592654 3.141592654"/>
                              <inertial pos="5.208648523e-06 0.004977895392 0.07010285226" mass="0.9352929404" fullinertia="0.001224 0.001136 0.00072 -0 -0 -4.3e-05"/>
                              <geom class="visual" mesh="dof5_link_1" pos="-0 -4e-06 -0.492859" material="silver_default"/>
                              <geom class="collision" mesh="dof5_link_1" pos="-0 -4e-06 -0.492859"/>
                              <body name="left_DOF6_LINK_1" pos="0 -0.025 0.0812" quat="1 0 0 0">
                                <joint name="left_Rev10" type="hinge" axis="0 1 0" range="-3.141592654 3.141592654"/>
                                  <inertial pos="-3.175600208e-08 -0.01167950147 0.04696416268" mass="0.5984706719" fullinertia="0.001836 0.001772 0.000381 0 -0 -0.000265"/>
                                  <geom class="visual" mesh="dof6_link_1" pos="-0 0.024996 -0.574059" material="silver_default"/>
                                  <geom class="collision" mesh="dof6_link_1" pos="-0 0.024996 -0.574059"/>
                                  <body name="left_DOF7_MOTOR_1" pos="-0 0.0255 0.122896" quat="1 0 0 0">
                                      <inertial pos="7.926952865e-05 3.749109242e-05 -0.03134546996" mass="0.5847003223" fullinertia="0.000404 0.00039 0.000324 0 2e-06 1e-06"/>
                                      <geom class="visual" mesh="dof7_motor_1" pos="0 -0.000504 -0.696955" material="silver_default"/>
                                      <geom class="collision" mesh="dof7_motor_1" pos="0 -0.000504 -0.696955"/>
                                  </body>
                                  <body name="left_TOP_1" pos="-0 0.0255 0.127896" quat="1 0 0 0">
                                      <inertial pos="-4.963925281e-07 -0.0001958278333 0.01611980647" mass="0.1530238863" fullinertia="4.6e-05 5e-05 5.5e-05 0 0 0"/>
                                      <geom class="visual" mesh="top_1" pos="0 -0.000504 -0.701955" material="silver_default"/>
                                      <geom class="collision" mesh="top_1" pos="0 -0.000504 -0.701955"/>
                                      <body name="left_wrist_link" pos="0 0 0.034" quat="1 0 0 0">
                                        <joint name="left_wrist" type="hinge" axis="0 0 1" range="-3.141592654 3.141592654"/>
                                          <inertial pos="0 0 0" mass="1e-06" fullinertia="1e-09 1e-09 1e-09 0 0 0"/>
                                          <body name="left_Hand_Dummy_Link" pos="0.0056 0.0126 0.06" quat="0.6618783286 0.2493588965 -0.6614811861 -0.2493588965">
                                              <!-- site 추가 -->
                                              <site name="gripper_left" pos="0 0 0" size="0.002"/>
                                              <inertial pos="0.005225293286 -0.01259942699 0.002045121406" mass="0.3910884626" fullinertia="0.0002614254715 0.0003440918145 0.0002488275565 -1.406195593e-05 1.954982259e-05 1.994317748e-06"/>
                                              <geom class="visual" mesh="lh_hand_dummy_link" material="blue"/>
                                              <geom class="collision" mesh="lh_hand_dummy_link"/>
                                              <body name="left_Mid_1" pos="0.0195 0 -0.044925" quat="0.892922933 0 -0 -0.4502095465">
                                                <joint name="left_Dummy_Mid_1" type="hinge" axis="0 0 1" range="-3.141592654 3.141592654"/>
                                                  <inertial pos="0.005334347782 0.02491453823 0.02688776818" mass="0.01135237004" fullinertia="5.979679476e-06 3.332989256e-06 3.378107291e-06 -4.309385476e-07 -1.501682507e-07 -1.017742299e-06"/>
                                                  <geom class="visual" mesh="lh_mid_1" pos="-0.01832400611 -0.006669392795 0.045" quat="0.984807753 0 0 0.1736481777" material="gray"/>
                                                  <geom class="collision" mesh="lh_mid_1" pos="-0.01832400611 -0.006669392795 0.045" quat="0.984807753 0 0 0.1736481777"/>
                                                  <body name="left_Top_1" pos="0.005 0.05 0.0265" quat="1 0 0 0">
                                                    <joint name="left_Mid_Top_1" type="hinge" axis="0 0 1" range="-3.141592654 3.141592654"/>
                                                      <inertial pos="0.0002393232736 0.02925116188 0.008500003673" mass="0.01814214378" fullinertia="3.336968409e-06 1.006678714e-06 3.17366042e-06 -7.041660453e-09 -1.983575166e-13 -1.124586174e-12"/>
                                                      <geom class="visual" mesh="lh_top_1" pos="-0.05942773049 -0.01495908382 0.0185" quat="0.9575713608 1.456586198e-15 -5.041016101e-15 -0.2881962681" material="green"/>
                                                      <geom class="collision" mesh="lh_top_1" pos="-0.05942773049 -0.01495908382 0.0185" quat="0.9575713608 1.456586198e-15 -5.041016101e-15 -0.2881962681"/>
                                                  </body>
                                              </body>
                                              <body name="left_Mid_2" pos="0.0195 0 0.044925" quat="5.467576059e-17 0.892922933 -0.4502095465 -2.756738401e-17">
                                                <joint name="left_Dummy_Mid_2" type="hinge" axis="0 0 -1" range="-3.141592654 3.141592654"/>
                                                  <inertial pos="0.007869027258 -0.03133595274 0.02577670879" mass="0.01804585427" fullinertia="8.550206262e-06 4.535872151e-06 5.088026604e-06 8.462213231e-07 -2.100064498e-07 8.503621249e-07"/>
                                                  <geom class="visual" mesh="lh_mid_2" pos="-0.01883555361 0.005046971379 0.045" quat="6.07084888e-17 0.9914448614 -0.1305261922 -7.992424175e-18" material="gray"/>
                                                  <geom class="collision" mesh="lh_mid_2" pos="-0.01883555361 0.005046971379 0.045" quat="6.07084888e-17 0.9914448614 -0.1305261922 -7.992424175e-18"/>
                                                  <body name="left_Top_2" pos="0.00456348 -0.05004173 0.0135" quat="6.123233996e-17 1 -1.387778781e-17 -8.497694209e-34">
                                                    <joint name="left_Mid_Top_2" type="hinge" axis="0 0 1" range="-3.141592654 3.141592654"/>
                                                      <inertial pos="-1.176159719e-05 0.02972293148 -0.01500000162" mass="0.03008199306" fullinertia="7.379369352e-06 3.550029558e-06 5.293784669e-06 -1.425365543e-07 1.063116371e-13 5.30658796e-13"/>
                                                      <geom class="visual" mesh="lh_top_2" pos="-0.05985214499 1.405545169e-05 -0.0315" quat="0.8987940463 0 -0 -0.4383711468" material="green"/>
                                                      <geom class="collision" mesh="lh_top_2" pos="-0.05985214499 1.405545169e-05 -0.0315" quat="0.8987940463 0 -0 -0.4383711468"/>
                                                  </body>
                                              </body>
                                              <body name="left_Mid_3" pos="-0.0195 0 -0.016425" quat="0.892922933 0 0 0.4502095465">
                                                <joint name="left_Dummy_Mid_3" type="hinge" axis="0 0 -1" range="-3.141592654 3.141592654"/>
                                                  <inertial pos="-0.005656949123 0.02594154443 0.02363307221" mass="0.01306378532" fullinertia="7.027515973e-06 4.035618881e-06 3.839200934e-06 5.288227031e-07 -1.816563283e-08 7.73979766e-08"/>
                                                  <geom class="visual" mesh="lh_mid_3" pos="0.01883555361 -0.005046971379 0.0165" quat="0.9914448614 0 -0 -0.1305261922" material="gray"/>
                                                  <geom class="collision" mesh="lh_mid_3" pos="0.01883555361 -0.005046971379 0.0165" quat="0.9914448614 0 -0 -0.1305261922"/>
                                                  <body name="left_Top_3" pos="-0.00456348 0.05004173 0.007" quat="6.123233996e-17 1 -1.387778781e-17 -8.497694209e-34">
                                                    <joint name="left_Mid_Top_3" type="hinge" axis="0 0 1" range="-3.141592654 3.141592654"/>
                                                      <inertial pos="0.0005304965066 -0.02971819922 -0.01500000149" mass="0.03008199306" fullinertia="7.3831774e-06 3.546221428e-06 5.293784669e-06 -7.562870916e-08 -3.178835318e-13 -6.469249066e-13"/>
                                                      <geom class="visual" mesh="lh_top_3" pos="0.05984327454 0.001030510699 -0.0095" quat="5.526740897e-17 0.9025852843 -0.4305110968 -2.636120184e-17" material="green"/>
                                                      <geom class="collision" mesh="lh_top_3" pos="0.05984327454 0.001030510699 -0.0095" quat="5.526740897e-17 0.9025852843 -0.4305110968 -2.636120184e-17"/>
                                                  </body>
                                              </body>
                                          </body>
                                      </body>
                                  </body>
                              </body>
                          </body>
                      </body>
                  </body>
              </body>
          </body>
      </body>
    </body>
  </worldbody>

  <actuator>
    <position name="right_Rev2" joint="right_Rev2" kp="50" kv="5"/>
    <position name="right_Rev3" joint="right_Rev3" kp="50" kv="5"/>
    <position name="right_Rev6" joint="right_Rev6" kp="50" kv="5"/>
    <position name="right_Rev7" joint="right_Rev7" kp="50" kv="5"/>
    <position name="right_Rev9" joint="right_Rev9" kp="50" kv="5"/>
    <position name="right_Rev10" joint="right_Rev10" kp="50" kv="5"/>
    <position name="left_Rev2" joint="left_Rev2" kp="50" kv="5"/>
    <position name="left_Rev3" joint="left_Rev3" kp="50" kv="5"/>
    <position name="left_Rev6" joint="left_Rev6" kp="50" kv="5"/>
    <position name="left_Rev7" joint="left_Rev7" kp="50" kv="5"/>
    <position name="left_Rev9" joint="left_Rev9" kp="50" kv="5"/>
    <position name="left_Rev10" joint="left_Rev10" kp="50" kv="5"/>
    <position name="right_wrist" joint="right_wrist" kp="50" kv="5"/>
    <position name="right_Dummy_Mid_1" joint="right_Dummy_Mid_1" kp="50" kv="5"/>
    <position name="right_Dummy_Mid_2" joint="right_Dummy_Mid_2" kp="50" kv="5"/>
    <position name="right_Dummy_Mid_3" joint="right_Dummy_Mid_3" kp="50" kv="5"/>
    <position name="right_Mid_Top_1" joint="right_Mid_Top_1" kp="50" kv="5"/>
    <position name="right_Mid_Top_2" joint="right_Mid_Top_2" kp="50" kv="5"/>
    <position name="right_Mid_Top_3" joint="right_Mid_Top_3" kp="50" kv="5"/>
    <position name="left_wrist" joint="left_wrist" kp="50" kv="5"/>
    <position name="left_Dummy_Mid_1" joint="left_Dummy_Mid_1" kp="50" kv="5"/>
    <position name="left_Dummy_Mid_2" joint="left_Dummy_Mid_2" kp="50" kv="5"/>
    <position name="left_Dummy_Mid_3" joint="left_Dummy_Mid_3" kp="50" kv="5"/>
    <position name="left_Mid_Top_1" joint="left_Mid_Top_1" kp="50" kv="5"/>
    <position name="left_Mid_Top_2" joint="left_Mid_Top_2" kp="50" kv="5"/>
    <position name="left_Mid_Top_3" joint="left_Mid_Top_3" kp="50" kv="5"/>
  </actuator>
</mujoco>